Workbook
Name avgstreamtosaleratio: cals!$S$16
Name bestreleasemonth: cals!$S$19
Name bestsellingalbum: cals!$P$13
Name bestsellingsrtist: cals!$P$16
Name highestfesalbum: cals!$S$10
Name highfesartist: cals!$S$13
Name Slicer_Label: #N/A
Name Slicer_Tier: #N/A
Name Slicer_Year: #N/A
Name topyear: cals!$P$10
Name uniqueartist: cals!$P$7

Sheet MasterData
A1: 📊 MASTER DATA TABLE — tblMaster | 800 Albums · 190 Artists · 2019–2026 |
A2: Index | B2: Rank | C2: Year | D2: AlbumName | E2: Artist | F2: ReleaseDate | G2: Label | H2: AlbumSales | I2: KoreaSales | J2: GlobalSales | K2: SpotifyStreams | L2: YoutubeStreams | M2: MelonStreams | N2: TwitterMentions | O2: WeversePosts | P2: FanCafeMembers | Q2: Spotify_N | R2: Youtube_N | S2: Melon_N | T2: Twitter_N | U2: Weverse_N | V2: FanCafe_N | W2: AlbumSales_N | X2: FES | Y2: NormalizedFES | Z2: Tier | AA2: Koreapct | AB2: Globalpct | AC2: Exportindex | AD2: Classification | AE2: AlbumStreams | AF2: Month
A3: 1 | B3: 1 | C3: 2019 | D3: MAP OF THE SOUL : PERSONA | E3: BTS | F3: 43567 | G3: HYBE | H3: 3718230 | I3: 1487292 | J3: 2230938 | K3: 6214552883 | L3: 3900000000 | M3: 300000000 | N3: 900000 | O3: 400000 | P3: 4000000 | Q3: 0.48232588 | R3: 0.42391304 | S3: 0.9375 | T3: 0.9 | U3: 0.88888889 | V3: 0.88888889 | W3: 0.67032214 | X3: 0.72146653 | Y3: 72.146653 | Z3: ICONIC | AA3: 0.4 | AB3: 0.6 | AC3: 1.5 | AD3: 🌍 Global-Led | AE3: 10414552883 | AF3: April
A4: 2 | B4: 2 | C4: 2019 | D4: 3RD ALBUM ‘An Ode’ | E4: Seventeen | F4: 43724 | G4: PLEDIS | H4: 858872 | I4: 343549 | J4: 515323 | K4: 2112884661 | L4: 1100000000 | M4: 200000000 | N4: 500000 | O4: 200000 | P4: 1800000 | Q4: 0.16398588 | R4: 0.11956522 | S4: 0.625 | T4: 0.5 | U4: 0.44444444 | V4: 0.4 | W4: 0.15483736 | X4: 0.33640343 | Y4: 33.640343 | Z4: SOLID | AA4: 0.40000023 | AB4: 0.59999977 | AC4: 1.4999985 | AD4: ⚖️ Balanced | AE4: 3412884661 | AF4: September
A5: 3 | B5: 3 | C5: 2019 | D5: OBSESSION - The 6th Album | E5: EXO | F5: 43796 | G5: SM | H5: 766294 | I5: 306518 | J5: 459776 | K5: 1488552118 | L5: 1400000000 | M5: 220000000 | N5: 500000 | O5: 220000 | P5: 2000000 | Q5: 0.11552999 | R5: 0.15217391 | S5: 0.6875 | T5: 0.5 | U5: 0.48888889 | V5: 0.44444444 | W5: 0.13814741 | X5: 0.35187507 | Y5: 35.187507 | Z5: SOLID | AA5: 0.40000052 | AB5: 0.59999948 | AC5: 1.4999967 | AD5: ⚖️ Balanced | AE5: 3108552118 | AF5: November
A6: 4 | B6: 4 | C6: 2019 | D6: 비상 : QUANTUM LEAP | E6: X1 | F6: 43626 | G6: BRANDNEW | H6: 580573 | I6: 290287 | J6: 290286 | K6: 244552118 | L6: 250000000 | M6: 180000000 | N6: 400000 | O6: 170000 | P6: 1600000 | Q6: 0.018980258 | R6: 0.027173913 | S6: 0.5625 | T6: 0.4 | U6: 0.37777778 | V6: 0.35555556 | W6: 0.10466564 | X6: 0.25170201 | Y6: 25.170201 | Z6: SOLID | AA6: 0.50000086 | AB6: 0.49999914 | AC6: 0.99999656 | AD6: ⚖️ Balanced | AE6: 674552118 | AF6: June
A7: 5 | B7: 5 | C7: 2019 | D7: BTS WORLD OST | E7: BTS | F7: 43644 | G7: HYBE | H7: 553364 | I7: 276682 | J7: 276682 | K7: 1122552118 | L7: 900000000 | M7: 260000000 | N7: 800000 | O7: 350000 | P7: 3500000 | Q7: 0.087123876 | R7: 0.097826087 | S7: 0.8125 | T7: 0.8 | U7: 0.77777778 | V7: 0.77777778 | W7: 0.099760408 | X7: 0.47160582 | Y7: 47.160582 | Z7: RISING | AA7: 0.5 | AB7: 0.5 | AC7: 1 | AD7: ⚖️ Balanced | AE7: 2282552118 | AF7: June
A8: 6 | B8: 6 | C8: 2019 | D8: City Lights - The 1st Mini Album | E8: Baekhyun | F8: 43656 | G8: SM | H8: 525935 | I8: 315561 | J8: 210374 | K8: 1122552118 | L8: 600000000 | M8: 210000000 | N8: 480000 | O8: 200000 | P8: 1900000 | Q8: 0.087123876 | R8: 0.065217391 | S8: 0.65625 | T8: 0.48 | U8: 0.44444444 | V8: 0.42222222 | W8: 0.094815511 | X8: 0.3112809 | Y8: 31.12809 | Z8: SOLID | AA8: 0.6 | AB8: 0.4 | AC8: 0.66666667 | AD8: 🇰🇷 Korea-Led | AE8: 1932552118 | AF8: July
A9: 7 | B9: 7 | C9: 2019 | D9: color on me | E9: Kang Daniel | F9: 43671 | G9: SM | H9: 500134 | I9: 300080 | J9: 200054 | K9: 822552118 | L9: 400000000 | M9: 200000000 | N9: 450000 | O9: 190000 | P9: 1800000 | Q9: 0.063840179 | R9: 0.043478261 | S9: 0.625 | T9: 0.45 | U9: 0.42222222 | V9: 0.4 | W9: 0.090164109 | X9: 0.28843948 | Y9: 28.843948 | Z9: SOLID | AA9: 0.5999992 | AB9: 0.4000008 | AC9: 0.66666889 | AD9: ⚖️ Balanced | AE9: 1422552118 | AF9: July
A10: 8 | B10: 8 | C10: 2019 | D10: 6TH MINI ALBUM `YOU MADE MY DAWN` | E10: Seventeen | F10: 43486 | G10: PLEDIS | H10: 475998 | I10: 285599 | J10: 190399 | K10: 1744552118 | L10: 1200000000 | M10: 200000000 | N10: 450000 | O10: 190000 | P10: 1800000 | Q10: 0.13539874 | R10: 0.13043478 | S10: 0.625 | T10: 0.45 | U10: 0.42222222 | V10: 0.4 | W10: 0.085812873 | X10: 0.31562399 | Y10: 31.562399 | Z10: SOLID | AA10: 0.60000042 | AB10: 0.39999958 | AC10: 0.6666655 | AD10: 🇰🇷 Korea-Led | AE10: 3144552118 | AF10: January
A11: 9 | B11: 9 | C11: 2019 | D11: Time_Slip - The 9th Album | E11: Super Junior | F11: 43752 | G11: SM | H11: 427647 | I11: 256588 | J11: 171059 | K11: 344552118 | L11: 300000000 | M11: 200000000 | N11: 450000 | O11: 190000 | P11: 1800000 | Q11: 0.02674149 | R11: 0.032608696 | S11: 0.625 | T11: 0.45 | U11: 0.42222222 | V11: 0.4 | W11: 0.077096159 | X11: 0.27847641 | Y11: 27.847641 | Z11: SOLID | AA11: 0.59999953 | AB11: 0.40000047 | AC11: 0.66666797 | AD11: ⚖️ Balanced | AE11: 844552118 | AF11: October
A12: 10 | B12: 10 | C12: 2019 | D12: Feel Special | E12: TWICE | F12: 43731 | G12: JYP | H12: 413459 | I12: 248075 | J12: 165384 | K12: 1988552118 | L12: 1800000000 | M12: 240000000 | N12: 550000 | O12: 240000 | P12: 2200000 | Q12: 0.15433615 | R12: 0.19565217 | S12: 0.75 | T12: 0.55 | U12: 0.53333333 | V12: 0.48888889 | W12: 0.074538348 | X12: 0.38674059 | Y12: 38.674059 | Z12: SOLID | AA12: 0.59999903 | AB12: 0.40000097 | AC12: 0.66666935 | AD12: ⚖️ Balanced | AE12: 4028552118 | AF12: September
A13: 11 | B13: 11 | C13: 2019 | D13: FANCY YOU | E13: TWICE | F13: 43577 | G13: JYP | H13: 394405 | I13: 236643 | J13: 157762 | K13: 2488552118 | L13: 2500000000 | M13: 240000000 | N13: 550000 | O13: 240000 | P13: 2200000 | Q13: 0.19314231 | R13: 0.27173913 | S13: 0.75 | T13: 0.55 | U13: 0.53333333 | V13: 0.48888889 | W13: 0.071103295 | X13: 0.40628263 | Y13: 40.628263 | Z13: RISING | AA13: 0.6 | AB13: 0.4 | AC13: 0.66666667 | AD13: 🇰🇷 Korea-Led | AE13: 5228552118 | AF13: April
A14: 12 | B14: 12 | C14: 2019 | D14: What a life - The 1st Mini Album | E14: EXO | F14: 43668 | G14: SM | H14: 391121 | I14: 234673 | J14: 156448 | K14: 611552118 | L14: 500000000 | M14: 200000000 | N14: 450000 | O14: 190000 | P14: 1800000 | Q14: 0.04746398 | R14: 0.054347826 | S14: 0.625 | T14: 0.45 | U14: 0.42222222 | V14: 0.4 | W14: 0.070511256 | X14: 0.28517777 | Y14: 28.517777 | Z14: SOLID | AA14: 0.60000102 | AB14: 0.39999898 | AC14: 0.66666383 | AD14: 🇰🇷 Korea-Led | AE14: 1311552118 | AF14: July
... A802: 800 | B802: 100 | C802: 2026 | D802: Emotion | E802: DKB | F802: 45792 | G802: SM | H802: 9251 | I802: 5551 | J802: 3700 | K802: 611552118 | L802: 2000000000 | M802: 110000000 | N802: 200000 | O802: 80000 | P802: 600000 | Q802: 0.04746398 | R802: 0.2173913 | S802: 0.34375 | T802: 0.2 | U802: 0.17777778 | V802: 0.13333333 | W802: 0.0016677694 | X802: 0.1643571 | Y802: 16.43571 | Z802: EMERGING | AA802: 0.60004324 | AB802: 0.39995676 | AC802: 0.66654657 | AD802: 🇰🇷 Korea-Led | AE802: 2721552118 | AF802: May

Sheet Artistlevel
A1: 🌍 GLOBAL vs KOREA SALES | Export Index · Geographic Classification · Market Leaders per Artist & 📱 STREAMING vs PHYSICAL SALES | Stream-to-Sale Ratio · Platform Battle · Loyalty Classification · Yearly Trend & 🆚 ALBUM COMPARISON | First Album vs Latest Album · Sales Growth · Stream Growth · Momentum · Status
A2: 📊 ARTIST-LEVEL GEOGRAPHIC BREAKDOWN (Export Index >1.0 = sells more globally than domestically) & STREAM-TO-SALE RATIO (Higher = streaming audience · Lower = physically loyal fanbase)
A3: Artist | B3: AlbumSales | C3: KoreaSales | D3: GlobalSales | E3: SpotifyStreams | F3: YoutubeStreams | G3: MelonStreams | H3: Koreapct | I3: Globalpct | J3: Exportindex | K3: Classification | L3: BestGlobalAlbum | M3: BestKoreaAlbum | N3: AlbumStreams | O3: StreamSaleRatio | P3: LoyaltyClass | Q3: Platformindex | R3: PrimaryPlatform | S3: Albums | T3: UniqueAlbums | U3: BestSales | V3: BestAlbum | W3: Label | X3: FirstAlbum | Y3: FirstSales | Z3: FirstStreams | AA3: LatestAlbum | AB3: LatestSales | AC3: LatestStreams | AD3: Sales Δ | AE3: SalesGrowth | AF3: Stream Δ | AG3: StreamGrowth | AH3: Momentum
A4: BTS | B4: 32669990 | C4: 15175994 | D4: 17493996 | E4: 296868707813 | F4: 243200000000 | G4: 15626000000 | H4: 0.46452399 | I4: 0.53547601 | J4: 1.1527414 | K4: ⚖️ Balanced | L4: MAP OF THE SOUL : 7 | M4: MAP OF THE SOUL : 7 | N4: 555694707813 | O4: 17009.332 | P4: 🎧 Stream-Heavy | Q4: 18.998381 | R4: 🌍 Spotify Global | S4: 55 | T4: 24 | U4: 5014888 | V4: MAP OF THE SOUL : 7 | W4: HYBE | X4: 2 Cool 4 Skool | Y4: 185183 | Z4: 10604237104 | AA4: ARIRANG (LP) | AB4: 185106 | AC4: 3770552118 | AD4: -77 | AE4: -0.00041580491 | AF4: -6833684986 | AG4: -0.64442967 | AH4: ⚖️ Softening
A5: Seventeen | B5: 42573334 | C5: 19856191 | D5: 22717143 | E5: 73745638405 | F5: 96400000000 | G5: 9640000000 | H5: 0.46639972 | I5: 0.53360028 | J5: 1.1440836 | K5: ⚖️ Balanced | L5: 10th Mini Album `FML` | M5: 10th Mini Album `FML` | N5: 179785638405 | O5: 4222.9636 | P5: 🏆 Physically Loyal | Q5: 7.6499625 | R5: 🌍 Spotify Global | S5: 50 | T5: 36 | U5: 5546930 | V5: 10th Mini Album `FML` | W5: PLEDIS | X5: 4th Mini Album `Al1` | Y5: 225173 | Z5: 2502552118 | AA5: 1st Mini Album `소야곡` (Weverse) | AB5: 44436 | AC5: 684552118 | AD5: -180737 | AE5: -0.8026584 | AF5: -1818000000 | AG5: -0.7264584 | AH5: ⬇️ Declining
A6: EXO | B6: 5754364 | C6: 2934429 | D6: 2819935 | E6: 8200191259 | F6: 12300000000 | G6: 1560000000 | H6: 0.50994845 | I6: 0.49005155 | J6: 0.96098253 | K6: ⚖️ Balanced | L6: EXIST - The 7th Album | M6: EXIST - The 7th Album | N6: 22060191259 | O6: 3833.6454 | P6: 🏆 Physically Loyal | Q6: 5.2565329 | R6: 🌍 Spotify Global | S6: 9 | T6: 9 | U6: 1644860 | V6: EXIST - The 7th Album | W6: SM | X6: What a life - The 1st Mini Album | Y6: 391121 | Z6: 1311552118 | AA6: REVERXE - The 8th Album | AB6: 678262 | AC6: 1334552118 | AD6: 287141 | AE6: 0.73414877 | AF6: 23000000 | AG6: 0.017536474 | AH6: 🚀 Accelerating
A7: X1 | B7: 642583 | C7: 327493 | D7: 315090 | E7: 489104236 | F7: 500000000 | G7: 360000000 | H7: 0.50965089 | I7: 0.49034911 | J7: 0.96212743 | K7: ⚖️ Balanced | L7: 비상 : QUANTUM LEAP | M7: 비상 : QUANTUM LEAP | N7: 1349104236 | O7: 2099.5019 | P7: 🏆 Physically Loyal | Q7: 1.3586229 | R7: 🇰🇷 Melon Korea | S7: 2 | T7: 2 | U7: 580573 | V7: 비상 : QUANTUM LEAP | W7: BRANDNEW | X7: 비상 : QUANTUM LEAP | Y7: 580573 | Z7: 674552118 | AA7: 비상 : QUANTUM LEAP | AB7: 580573 | AC7: 674552118 | AD7: 0 | AE7: 0 | AF7: 0 | AG7: 0 | AH7: ⚖️ Softening
A8: Baekhyun | B8: 4608479 | C8: 2640555 | D8: 1967924 | E8: 4963055742 | F8: 8200000000 | G8: 1150000000 | H8: 0.57297755 | I8: 0.42702245 | J8: 0.74526908 | K8: ⚖️ Balanced | L8: Hello, World - The 4th Mini Album | M8: Hello, World - The 4th Mini Album | N8: 14313055742 | O8: 3105.809 | P8: 🏆 Physically Loyal | Q8: 4.3157006 | R8: ⚖️ Mixed | S8: 6 | T8: 6 | U8: 1245318 | V8: Hello, World - The 4th Mini Album | W8: SM | X8: City Lights - The 1st Mini Album | Y8: 525935 | Z8: 1932552118 | AA8: Essence of Reverie | AB8: 643272 | AC8: 3702552118 | AD8: 117337 | AE8: 0.22310171 | AF8: 1770000000 | AG8: 0.91588733 | AH8: 📈 Growing
A9: Kang Daniel | B9: 1743535 | C9: 1046120 | D9: 697415 | E9: 3662653809 | F9: 7200000000 | G9: 1040000000 | H9: 0.59999943 | I9: 0.40000057 | J9: 0.66666826 | K9: ⚖️ Balanced | L9: color on me | M9: color on me | N9: 11902653809 | O9: 6826.7364 | P9: ⚖️ Balanced | Q9: 3.5217825 | R9: ⚖️ Mixed | S9: 7 | T9: 7 | U9: 500134 | V9: color on me | W9: KONNECT | X9: color on me | Y9: 500134 | Z9: 1422552118 | AA9: PULSEPHASE | AB9: 12500 | AC9: 3172552118 | AD9: -487634 | AE9: -0.9750067 | AF9: 1750000000 | AG9: 1.2301834 | AH9: ⬇️ Declining
A10: Super Junior | B10: 2292081 | C10: 1345345 | D10: 946736 | E10: 4165418459 | F10: 8100000000 | G10: 1700000000 | H10: 0.58695352 | I10: 0.41304648 | J10: 0.70371243 | K10: ⚖️ Balanced | L10: The Renaissance - The 10th Album | M10: The Renaissance - The 10th Album | N10: 13965418459 | O10: 6092.8992 | P10: ⚖️ Balanced | Q10: 2.4502462 | R10: ⚖️ Mixed | S10: 10 | T10: 10 | U10: 442742 | V10: The Renaissance - The 10th Album | W10: SM | X10: DANGER - The 3rd Mini Album | Y10: 89959 | Z10: 5262552118 | AA10: Super Junior25 - The 12th Album | AB10: 299038 | AC10: 1364552118 | AD10: 209079 | AE10: 2.3241588 | AF10: -3898000000 | AG10: -0.74070525 | AH10: 🚀 Accelerating
A11: TWICE | B11: 10993696 | C11: 6204042 | D11: 4789654 | E11: 24825274625 | F11: 39000000000 | G11: 3530000000 | H11: 0.56432723 | I11: 0.43567277 | J11: 0.77202153 | K11: ⚖️ Balanced | L11: READY TO BE | M11: READY TO BE | N11: 67355274625 | O11: 6126.718 | P11: ⚖️ Balanced | Q11: 7.0326557 | R11: 🌍 Spotify Global | S11: 17 | T11: 17 | U11: 1674143 | V11: READY TO BE | W11: JYP | X11: What is Love? | Y11: 50877 | Z11: 5172552118 | AA11: THIS IS FOR | AB11: 765171 | AC11: 3462552118 | AD11: 714294 | AE11: 14.039625 | AF11: -1710000000 | AG11: -0.33059116 | AH11: 🚀 Accelerating
A12: NCT DREAM | B12: 19935099 | C12: 9278971 | D12: 10656128 | E12: 24389390441 | F12: 37900000000 | G12: 3780000000 | H12: 0.46545899 | I12: 0.53454101 | J12: 1.148417 | K12: ⚖️ Balanced | L12: ISTJ - The 3rd Album | M12: ISTJ - The 3rd Album | N12: 66069390441 | O12: 3314.2243 | P12: 🏆 Physically Loyal | Q12: 6.4522197 | R12: 🌍 Spotify Global | S12: 19 | T12: 16 | U12: 3369118 | V12: ISTJ - The 3rd Album | W12: SM | X12: We Boom - The 3rd Mini Album | Y12: 457608 | Z12: 4177104236 | AA12: Go Back To The Future | AB12: 959579 | AC12: 2694552118 | AD12: 501971 | AE12: 1.0969454 | AF12: -1482552118 | AG12: -0.35492342 | AH12: 🚀 Accelerating
A13: BLACKPINK | B13: 6857027 | C13: 3010529 | D13: 3846498 | E13: 38279470270 | F13: 68600000000 | G13: 2838000000 | H13: 0.4390429 | I13: 0.5609571 | J13: 1.2776818 | K13: ⚖️ Balanced | L13: BORN PINK | M13: BORN PINK | N13: 109717470270 | O13: 16000.735 | P13: 🎧 Stream-Heavy | Q13: 13.488185 | R13: 🌍 Spotify Global | S13: 10 | T13: 6 | U13: 2768482 | V13: BORN PINK | W13: YG | X13: SQUARE UP | Y13: 57332 | Z13: 7574552118 | AA13: DEADLINE | AB13: 1750692 | AC13: 4520552118 | AD13: 1693360 | AE13: 29.536036 | AF13: -3054000000 | AG13: -0.40319216 | AH13: 🚀 Accelerating
A14: GOT7 | B14: 1867675 | C14: 1120605 | D14: 747070 | E14: 3726421378 | F14: 5100000000 | G14: 1000000000 | H14: 0.6 | I14: 0.4 | J14: 0.66666667 | K14: 🇰🇷 Korea-Led | L14: GOT7 | M14: GOT7 | N14: 9826421378 | O14: 5261.3123 | P14: ⚖️ Balanced | Q14: 3.7264214 | R14: ⚖️ Mixed | S14: 5 | T14: 5 | U14: 459254 | V14: GOT7 | W14: JYP | X14: SPINNING TOP : BETWEEN SECURITY & INSECURITY | Y14: 314948 | Z14: 1722552118 | AA14: GOT7 | AB14: 459254 | AC14: 2822552118 | AD14: 144306 | AE14: 0.45818992 | AF14: 1100000000 | AG14: 0.63858735 | AH14: 📈 Growing
A15: NCT 127 | B15: 11184297 | C15: 5601756 | D15: 5582541 | E15: 12362209596 | F15: 18800000000 | G15: 2360000000 | H15: 0.50085902 | I15: 0.49914098 | J15: 0.99656983 | K15: ⚖️ Balanced | L15: Sticker - The 3rd Album | M15: Sticker - The 3rd Album | N15: 33522209596 | O15: 2997.2567 | P15: 🏆 Physically Loyal | Q15: 5.2382244 | R15: 🌍 Spotify Global | S15: 11 | T15: 11 | U15: 2427559 | V15: Sticker - The 3rd Album | W15: SM | X15: NCT #127 WE ARE SUPERHUMAN - The 4th Mini Album | Y15: 265762 | Z15: 1998552118 | AA15: WALK - The 6th Album | AB15: 915337 | AC15: 3122552118 | AD15: 649575 | AE15: 2.4441982 | AF15: 1124000000 | AG15: 0.56240715 | AH15: 🚀 Accelerating
... A193: DKB | B193: 9251 | C193: 5551 | D193: 3700 | E193: 611552118 | F193: 2000000000 | G193: 110000000 | H193: 0.60004324 | I193: 0.39995676 | J193: 0.66654657 | K193: 🇰🇷 Korea-Led | L193: Emotion | M193: Emotion | N193: 2721552118 | O193: 294190.05 | P193: 🎧 Stream-Heavy | Q193: 5.5595647 | R193: 🌍 Spotify Global | S193: 1 | T193: 1 | U193: 9251 | V193: Emotion | W193: SM | X193: Emotion | Y193: 9251 | Z193: 2721552118 | AA193: Emotion | AB193: 9251 | AC193: 2721552118 | AD193: 0 | AE193: 0 | AF193: 0 | AG193: 0 | AH193: ⚖️ Softening

Sheet labelwise
A1: 📊 LABEL ANALYSIS | Slicer: Year · Tier | Market share by record label
A2: Label | B2: Albums | C2: TotalSales | D2: KoreaSales | E2: GlobalSales | F2: SpotifyStreams | G2: YoutubeStreams | H2: MelonStreams | I2: Artists | J2: MarketShare | K2: Exportindex | L2: Index
A3: SM | B3: 169 | C3: 86807060 | D3: 45016001 | E3: 41791059 | F3: 148951295505 | G3: 281000000000 | H3: 30550000000 | I3: 63 | J3: 0.21245486 | K3: 0.9283601 | L3: 1
A4: HYBE | B4: 114 | C4: 69388690 | D4: 33414427 | E4: 35974263 | F4: 398408177711 | G4: 416300000000 | H4: 28756000000 | I4: 27 | J4: 0.16982449 | K4: 1.0766087 | L4: 2
A5: JYP | B5: 72 | C5: 55506055 | D5: 27060887 | E5: 28445168 | F5: 94630194349 | G5: 151700000000 | H5: 14548000000 | I5: 17 | J5: 0.13584761 | K5: 1.0511543 | L5: 3
A6: PLEDIS | B6: 55 | C6: 44410881 | D6: 20845230 | E6: 23565651 | F6: 78579630082 | G6: 105700000000 | H6: 11010000000 | I6: 10 | J6: 0.10869286 | K6: 1.1305057 | L6: 4
A7: YG | B7: 42 | C7: 19017969 | D7: 10165541 | E7: 8852428 | F7: 63195025965 | G7: 123300000000 | H7: 8410000000 | I7: 20 | J7: 0.046545292 | K7: 0.87082704 | L7: 5
A8: BELIFT LAB | B8: 27 | C8: 18885862 | D8: 9347852 | E8: 9538010 | F8: 39194920646 | G8: 65400000000 | H8: 5390000000 | I8: 7 | J8: 0.046221969 | K8: 1.0203424 | L8: 6
A9: STARSHIP | B9: 41 | C9: 18639303 | D9: 9983664 | E9: 8655639 | F9: 37121658400 | G9: 69200000000 | H9: 7005000000 | I9: 15 | J9: 0.045618531 | K9: 0.8669802 | L9: 7
A10: KQ | B10: 31 | C10: 15416952 | D10: 8589764 | E10: 6827188 | F10: 26350013633 | G10: 47000000000 | H10: 5360000000 | I10: 7 | J10: 0.037732028 | K10: 0.79480507 | L10: 8
A11: IST | B11: 41 | C11: 13196378 | D11: 7688958 | E11: 5507420 | F11: 18242671151 | G11: 42450000000 | H11: 5530000000 | I11: 25 | J11: 0.032297312 | K11: 0.71627651 | L11: 9
A12: WAKEONE | B12: 16 | C12: 9800687 | D12: 5162221 | E12: 4638466 | F12: 10959833888 | G12: 24300000000 | H12: 2320000000 | I12: 7 | J12: 0.02398657 | K12: 0.89854076 | L12: 10
A13: ADOR | B13: 12 | C13: 7739865 | D13: 4252138 | E13: 3487727 | F13: 38606625416 | G13: 52200000000 | H13: 3100000000 | I13: 1 | J13: 0.018942837 | K13: 0.82022902 | L13: 11
A14: KOZ | B14: 14 | C14: 5620772 | D14: 3256007 | E14: 2364765 | F14: 7470296528 | G14: 17100000000 | H14: 1485000000 | I14: 9 | J14: 0.013756489 | K14: 0.72627762 | L14: 12
... A40: SWING | B40: 1 | C40: 52426 | D40: 31456 | E40: 20970 | F40: 1122552118 | G40: 900000000 | H40: 200000000 | I40: 1 | J40: 0.00012830936 | K40: 0.66664547 | L40: 38

Sheet cals
A1: ⚙️ CALCULATIONS ENGINE — Referenced by all sheets
A2: TABLE 1 — YEARLY SALES SUMMARY | L2: KPI SUMMARY
A3: Row Labels | B3: Sum of GlobalSales | C3: Sum of KoreaSales | L3: Total Physical Sales | M3: =GETPIVOTDATA("TotalPhysicalSales",$P$3) -> 408590601 | P3: TotalPhysicalSales | Q3: Sum of AlbumStreams | R3: Count of AlbumName | S3: Sum of SpotifyStreams | T3: Sum of YoutubeStreams | U3: Sum of MelonStreams | V3: Sum of KoreaSales | W3: Sum of GlobalSales | X3: Average of Exportindex
A4: 2019 | B4: 9602547 | C4: 11448633 | L4: Total Spotify Streams | M4: =GETPIVOTDATA("Sum of SpotifyStreams",$P$3) -> 1070653784544 | P4: 408590601 | Q4: 2810822784544 | R4: 800 | S4: 1070653784544 | T4: 1591660000000 | U4: 148509000000 | V4: 210339271 | W4: 198251330 | X4: 0.75333283
A5: 2020 | B5: 16273941 | C5: 18639613 | L5: Total YouTube Views | M5: =GETPIVOTDATA("Sum of YoutubeStreams",$P$3) -> 1591660000000
A6: 2021 | B6: 21167555 | C6: 24301332 | L6: Total Melon Streams | M6: =GETPIVOTDATA("Sum of MelonStreams",$P$3) -> 148509000000 | P6: Distinct Count of Artist
A7: 2022 | B7: 30002211 | C7: 30474703 | L7: Total Albums Tracked | M7: =GETPIVOTDATA("Count of AlbumName",$P$3) -> 800 | P7: 190
A8: 2023 | B8: 47914399 | C8: 46253428 | L8: Total Artists Tracked | M8: =GETPIVOTDATA("[Measures].[Distinct Count of Artist]",$P$6) -> 190
A9: 2024 | B9: 34028544 | C9: 37169583 | L9: Best Selling Album | M9: =bestsellingalbum -> 10th Mini Album `FML` | P9: Row Labels | Q9: Sum of AlbumSales | S9: Row Labels | T9: Sum of NormalizedFES
A10: 2025 | B10: 30619196 | C10: 33996126 | L10: Best Selling Artist | M10: =bestsellingsrtist -> Seventeen | P10: 2023 | Q10: 94167827 | S10: LOVE YOURSELF 轉 `Tear` | T10: 306.63054
A11: 2026 | B11: 8642937 | C11: 8055853 | L11: Peak Year (sales) | M11: =topyear -> 2023
L12: Avg Stream-to-Sale Ratio | M12: =GETPIVOTDATA("StreamSaleRatio",$S$15) -> 41845.307 | P12: Row Labels | Q12: Sum of AlbumSales | S12: Row Labels | T12: Sum of NormalizedFES
L13: Highest FES Album | M13: =highestfesalbum -> LOVE YOURSELF 轉 `Tear` | P13: 10th Mini Album `FML` | Q13: 5546930 | S13: BTS | T13: 3445.2859
A14: TABLE 1 — YEARLY STREAMS SUMMARY | L14: Highest FES Artist | M14: =highfesartist -> BTS
A15: Row Labels | B15: Sum of SpotifyStreams | C15: Sum of YoutubeStreams | D15: Sum of MelonStreams | L15: Best Release Month | M15: =bestreleasemonth -> May | P15: Row Labels | Q15: Sum of AlbumSales | S15: Average of StreamSaleRatio
A16: 2019 | B16: 149822469446 | C16: 128150000000 | D16: 19830000000 | P16: Seventeen | Q16: 42573334 | S16: 41845.307
A17: 2020 | B17: 131287587816 | C17: 151710000000 | D17: 20080000000
A18: 2021 | B18: 173044977336 | C18: 207700000000 | D18: 21800000000 | S18: Row Labels | T18: Sum of AlbumSales
A19: 2022 | B19: 169604505505 | C19: 226800000000 | D19: 21070000000 | S19: May | T19: 54507958
A20: 2023 | B20: 175039143630 | C20: 274500000000 | D20: 20860000000
A21: 2024 | B21: 107076544343 | C21: 220300000000 | D21: 16510000000
A22: 2025 | B22: 77025778234 | C22: 175800000000 | D22: 13885000000
A23: 2026 | B23: 87752778234 | C23: 206700000000 | D23: 14474000000
A38: 📅 TIME TRENDS | Yearly Market Growth · Monthly Patterns · 8-Year Trajectory (2019–2026)
A39: 📈 8-YEAR MARKET PERFORMANCE — Physical Sales & Streaming Growth
A40: Row Labels | B40: YOY Sales Growth% | C40: YOY Streams Growth%
A41: 2019
A42: 2020 | B42: 0.65850817 | C42: 0.017713481
A43: 2021 | B43: 0.30232766 | C43: 0.32819117
A44: 2022 | B44: 0.33007245 | C44: 0.037087851
A45: 2023 | B45: 0.55708717 | C45: 0.12677334
A46: 2024 | B46: -0.24392301 | C46: -0.26894734
A47: 2025 | B47: -0.092457559 | C47: -0.22442217
A48: 2026 | B48: -0.74156609 | C48: 0.15828382
A51: 📅 MONTHLY RELEASE PATTERN — Release timing strategy by month
A52: Row Labels | B52: AlbumsReleased | C52: TotalAlbumSales | D52: AverageAlbumSales
A53: January | B53: 48 | C53: 23061997 | D53: 480458.27
A54: February | B54: 76 | C54: 26324427 | D54: 346374.04
A55: March | B55: 69 | C55: 32805348 | D55: 475439.83
A56: April | B56: 77 | C56: 38762009 | D56: 503402.71
...

Sheet Dashboard
A1: 🎵 ALBUM SALES & FAN ENGAGEMENT DASHBOARD
A2: 800 Albums · 190 Artists · 2019–2026 · Pivot Tables · Slicers · Timeline
D3: 🗓️ YEAR SLICER | F3: 🏷️ LABEL SLICER | L3: 📌 KEY PERFORMANCE INDICATORS — 2019–2026 Combined
L6: =GETPIVOTDATA("TotalPhysicalSales",cals!$P$3) -> 408590601 | Q6: =GETPIVOTDATA("Sum of AlbumStreams",cals!$P$3) -> 2810822784544 | V6: =topyear -> 2023
L9: 👑 TOP ARTIST (TOTAL SALES) | Q9: 🏆 BEST SELLING ALBUM | V9: 🎯 UNIQUE ARTISTS
L11: =bestsellingsrtist -> Seventeen | Q11: =bestsellingalbum -> 10th Mini Album `FML` | V11: =uniqueartist -> 190
L14: AVERAGE STREAM:SALE | Q14: 🏆 BEST RELEASE MONTH | V14: 📀 ALBUMS TRACKED
L16: =avgstreamtosaleratio -> 41845.307 | Q16: =bestreleasemonth -> May | V16: =GETPIVOTDATA("Count of AlbumName",cals!$P$3) -> 800

Sheet GlobalvsKorea
A1: 🎵 ALBUM SALES & FAN ENGAGEMENT DASHBOARD
A2: 800 Albums · 190 Artists · 2019–2026 · Pivot Tables · Slicers · Timeline
D3: 🗓️ YEAR SLICER | I3: 🇰🇷 Total Korea Sales | M3: 📊Average Exportindex | Q3: 🌍 Total Global Sales
I5: =GETPIVOTDATA("Sum of KoreaSales",cals!$P$3) -> 210339271 | M5: =GETPIVOTDATA("Average of Exportindex",cals!$P$3) -> 0.75333283 | Q5: =GETPIVOTDATA("Sum of GlobalSales",cals!$P$3) -> 198251330

Sheet FanEngagement
A1: 🎵 ALBUM SALES & FAN ENGAGEMENT DASHBOARD
A2: 800 Albums · 190 Artists · 2019–2026 · Pivot Tables · Slicers · Timeline
D3: 🗓️ YEAR SLICER | H3: 🏅 TIER SLICER | K3: 👑 HIGHEST FES ARTIST | P3: 👑 HIGHEST FES ALBUM
K5: =highfesartist -> BTS | P5: =highestfesalbum -> LOVE YOURSELF 轉 `Tear`

Sheet Streaming
A1: 🎵 K-POP ALBUM SALES & FAN ENGAGEMENT DASHBOARD
A2: 800 Albums · 190 Artists · 2019–2026 · Pivot Tables · Slicers · Timeline
D3: 🗓️ YEAR SLICER | H3: 🏷️ LABEL SLICER | P3: 🎧 TOTAL SPOTIFY STREAMS | W3: ▶️ TOTAL YOUTUBE VIEWS | AE3: 🎧 TOTAL MWLON STREAMS
P5: =GETPIVOTDATA("Sum of SpotifyStreams",cals!$P$3) -> 1070653784544 | W5: =GETPIVOTDATA("Sum of YoutubeStreams",cals!$P$3) -> 1591660000000 | AE5: =GETPIVOTDATA("Sum of MelonStreams",cals!$P$3) -> 148509000000

Sheet rawdata
A2: Index | B2: Rank | C2: Year | D2: AlbumName | E2: Artist | F2: ReleaseDate | G2: Label | H2: AlbumSales | I2: KoreaSales | J2: GlobalSales | K2: SpotifyStreams | L2: YoutubeStreams | M2: MelonStreams | N2: TwitterMentions | O2: WeversePosts | P2: FanCafeMembers
A3: 1 | B3: 1 | C3: 2019 | D3: MAP OF THE SOUL : PERSONA | E3: BTS | F3: 43567 | G3: HYBE | H3: 3718230 | I3: 1487292 | J3: 2230938 | K3: 6214552883 | L3: 3900000000 | M3: 300000000 | N3: 900000 | O3: 400000 | P3: 4000000
A4: 2 | B4: 2 | C4: 2019 | D4: 3RD ALBUM ‘An Ode’ | E4: Seventeen | F4: 43724 | G4: PLEDIS | H4: 858872 | I4: 343549 | J4: 515323 | K4: 2112884661 | L4: 1100000000 | M4: 200000000 | N4: 500000 | O4: 200000 | P4: 1800000
A5: 3 | B5: 3 | C5: 2019 | D5: OBSESSION - The 6th Album | E5: EXO | F5: 43796 | G5: SM | H5: 766294 | I5: 306518 | J5: 459776 | K5: 1488552118 | L5: 1400000000 | M5: 220000000 | N5: 500000 | O5: 220000 | P5: 2000000
A6: 4 | B6: 4 | C6: 2019 | D6: 비상 : QUANTUM LEAP | E6: X1 | F6: 43626 | G6: BRANDNEW | H6: 580573 | I6: 290287 | J6: 290286 | K6: 244552118 | L6: 250000000 | M6: 180000000 | N6: 400000 | O6: 170000 | P6: 1600000
A7: 5 | B7: 5 | C7: 2019 | D7: BTS WORLD OST | E7: BTS | F7: 43644 | G7: HYBE | H7: 553364 | I7: 276682 | J7: 276682 | K7: 1122552118 | L7: 900000000 | M7: 260000000 | N7: 800000 | O7: 350000 | P7: 3500000
A8: 6 | B8: 6 | C8: 2019 | D8: City Lights - The 1st Mini Album | E8: Baekhyun | F8: 43656 | G8: SM | H8: 525935 | I8: 315561 | J8: 210374 | K8: 1122552118 | L8: 600000000 | M8: 210000000 | N8: 480000 | O8: 200000 | P8: 1900000
A9: 7 | B9: 7 | C9: 2019 | D9: color on me | E9: Kang Daniel | F9: 43671 | G9: SM | H9: 500134 | I9: 300080 | J9: 200054 | K9: 822552118 | L9: 400000000 | M9: 200000000 | N9: 450000 | O9: 190000 | P9: 1800000
A10: 8 | B10: 8 | C10: 2019 | D10: 6TH MINI ALBUM `YOU MADE MY DAWN` | E10: Seventeen | F10: 43486 | G10: PLEDIS | H10: 475998 | I10: 285599 | J10: 190399 | K10: 1744552118 | L10: 1200000000 | M10: 200000000 | N10: 450000 | O10: 190000 | P10: 1800000
A11: 9 | B11: 9 | C11: 2019 | D11: Time_Slip - The 9th Album | E11: Super Junior | F11: 43752 | G11: SM | H11: 427647 | I11: 256588 | J11: 171059 | K11: 344552118 | L11: 300000000 | M11: 200000000 | N11: 450000 | O11: 190000 | P11: 1800000
A12: 10 | B12: 10 | C12: 2019 | D12: Feel Special | E12: TWICE | F12: 43731 | G12: JYP | H12: 413459 | I12: 248075 | J12: 165384 | K12: 1988552118 | L12: 1800000000 | M12: 240000000 | N12: 550000 | O12: 240000 | P12: 2200000
A13: 11 | B13: 11 | C13: 2019 | D13: FANCY YOU | E13: TWICE | F13: 43577 | G13: JYP | H13: 394405 | I13: 236643 | J13: 157762 | K13: 2488552118 | L13: 2500000000 | M13: 240000000 | N13: 550000 | O13: 240000 | P13: 2200000
A14: 12 | B14: 12 | C14: 2019 | D14: What a life - The 1st Mini Album | E14: EXO | F14: 43668 | G14: SM | H14: 391121 | I14: 234673 | J14: 156448 | K14: 611552118 | L14: 500000000 | M14: 200000000 | N14: 450000 | O14: 190000 | P14: 1800000
... A802: 800 | B802: 100 | C802: 2026 | D802: Emotion | E802: DKB | F802: 45792 | G802: SM | H802: 9251 | I802: 5551 | J802: 3700 | K802: 611552118 | L802: 2000000000 | M802: 110000000 | N802: 200000 | O802: 80000 | P802: 600000
